Workbook

Sheet How to Use
A1: REFINED RADIO — MASTER CONTROL SHEET
A3: Edit this file, send it back, and say 'rebuild the radio from this sheet.'
A5: Preview column: | B5: click the ▶ Play link to hear the song in a small player, then set its Genre/Style.
A6: Pull a song: | B6: set In Rotation? = No.
A7: Rename on air: | B7: edit Display Name.
A8: Gold columns | B8: are read back into the site.
A9: NEW tag | B9: means a recently added song.

Sheet Song Library
A1: SONG LIBRARY — click ▶ Preview to hear each song, then set Genre/Style. Gold columns rebuild the site.
A2: # | B2: ▶ Preview | C2: File (src) — known name | D2: Display Name (on station) | E2: Artist | F2: Genre | G2: Style / Version | H2: Family | I2: Versions | J2: New? | K2: In Rotation? | L2: Notes
A3: 1 | B3: ▶ Play | C3: music/A Vapor Breath.mp3 | D3: A Vapor Breath (2000s Alternative Metal) | E3: RRN | F3: Christian 2000s Alternative Metal | G3: 2000s Alternative Metal | H3: A Vapor Breath | I3: =COUNTIF($H$3:$H$248,H3) -> 1 | K3: Yes
A4: 2 | B4: ▶ Play | C4: music/A Whisper From Hannah Country Rock.mp3 | D4: A Whisper from Hannah (Southern Blues Rock) | E4: RRN | F4: Christian Southern Blues Rock | G4: Southern Blues Rock | H4: A Whisper from Hannah | I4: =COUNTIF($H$3:$H$248,H4) -> 1 | K4: Yes
A5: 3 | B5: ▶ Play | C5: music/ABIDE IN YOU— DANCE FLOOR ANTHEM.mp3 | D5: Abide in You (Dance) | E5: RRN | F5: Christian Dance | G5: Dance | H5: Abide in You | I5: =COUNTIF($H$3:$H$248,H5) -> 2 | K5: Yes
A6: 4 | B6: ▶ Play | C6: music/ABIDE IN YOU— Post-Grunge.mp3 | D6: Abide in You (Worship Rock) | E6: RRN | F6: Worship Rock | G6: Worship Rock | H6: Abide in You | I6: =COUNTIF($H$3:$H$248,H6) -> 2 | K6: Yes
A7: 5 | B7: ▶ Play | C7: music/Alabaster_Box.mp3 | D7: Alabaster Box (Teaching) | E7: RRN Teaching | F7: Biblical Teaching | G7: Teaching | H7: Alabaster Box | I7: =COUNTIF($H$3:$H$248,H7) -> 1 | K7: Yes
A8: 6 | B8: ▶ Play | C8: music/Alabaster Tears (Outlaw Country).mp3 | D8: Alabaster Tears (Outlaw Country) | E8: RRN | F8: Christian Outlaw Country | G8: Outlaw Country | H8: Alabaster Tears | I8: =COUNTIF($H$3:$H$248,H8) -> 1 | J8: NEW | K8: Yes
A9: 7 | B9: ▶ Play | C9: music/Among the Tombs (Outlaw Country).mp3 | D9: Among the Tombs (Outlaw Country) | E9: RRN | F9: Christian Outlaw Country | G9: Outlaw Country | H9: Among the Tombs | I9: =COUNTIF($H$3:$H$248,H9) -> 1 | J9: NEW | K9: Yes
A10: 8 | B10: ▶ Play | C10: music/Backside_Desert.mp3 | D10: Backside of the Desert (Teaching) | E10: RRN Teaching | F10: Biblical Teaching | G10: Teaching | H10: Backside of the Desert | I10: =COUNTIF($H$3:$H$248,H10) -> 1 | K10: Yes
A11: 9 | B11: ▶ Play | C11: music/Beauty for Ashes (1).mp3 | D11: Beauty for Ashes (Southern Blues Rock) | E11: RRN | F11: Christian Southern Blues Rock | G11: Southern Blues Rock | H11: Beauty for Ashes | I11: =COUNTIF($H$3:$H$248,H11) -> 1 | K11: Yes
A12: 10 | B12: ▶ Play | C12: music/Beauty Holiness Radio.mp3 | D12: Beauty Holiness (Worship) | E12: RRN | F12: Contemporary Worship | G12: Worship | H12: Beauty Holiness | I12: =COUNTIF($H$3:$H$248,H12) -> 1 | K12: Yes
A13: 11 | B13: ▶ Play | C13: music/Beauty Holiness Spanish Guitar (1).mp3 | D13: Beauty Holiness: Spanish Guitar Version (Southern Blues Rock) | E13: RRN | F13: Christian Southern Blues Rock | G13: Southern Blues Rock | H13: Beauty Holiness Spanish Guitar | I13: =COUNTIF($H$3:$H$248,H13) -> 1 | K13: Yes
A14: 13 | B14: ▶ Play | C14: music/Beyond the Shadows.mp3 | D14: Beyond the Shadows (Pop) | E14: RRN | F14: Christian Pop | G14: Pop | H14: Beyond the Shadows | I14: =COUNTIF($H$3:$H$248,H14) -> 1 | K14: Yes
A15: 14 | B15: ▶ Play | C15: music/Bless Your Name (Bluegrass).mp3 | D15: Bless Your Name (Bluegrass) | E15: RRN | F15: Christian Bluegrass | G15: Bluegrass | H15: Bless Your Name | I15: =COUNTIF($H$3:$H$248,H15) -> 1 | J15: NEW | K15: Yes
A16: 17 | B16: ▶ Play | C16: music/Blessed & a Mess Bounce Drop Country Rap (1).mp3 | D16: Blessed & a Mess (Country Rap Bounce Mix) | E16: RRN | F16: Christian Bounce Drop | G16: Bounce Drop | H16: Blessed & a Mess Country Rap | I16: =COUNTIF($H$3:$H$248,H16) -> 1 | K16: Yes
A17: 21 | B17: ▶ Play | C17: music/Bow Before Your Thone (K - Pop).mp3 | D17: Bow Before Your Throne (K-Pop) | E17: RRN | F17: Christian K-Pop | G17: K-Pop | H17: Bow Before Your Throne | I17: =COUNTIF($H$3:$H$248,H17) -> 1 | J17: NEW | K17: Yes
A18: 22 | B18: ▶ Play | C18: music/Break the Silence”.mp3 | D18: Break the Silence (Praise & Worship) | E18: RRN | F18: Praise & Worship | G18: Praise & Worship | H18: Break the Silence | I18: =COUNTIF($H$3:$H$248,H18) -> 1 | K18: Yes
A19: 23 | B19: ▶ Play | C19: music/Breath on Glass (1).mp3 | D19: Breath on Glass (Hip-Hop) | E19: RRN | F19: Christian Hip-Hop | G19: Hip-Hop | H19: Breath on Glass | I19: =COUNTIF($H$3:$H$248,H19) -> 1 | K19: Yes
A20: 25 | B20: ▶ Play | C20: music/Broken but Yours (Worship).mp3 | D20: Broken but Yours (Worship) | E20: RRN | F20: Contemporary Worship | G20: Worship | H20: Broken but Yours | I20: =COUNTIF($H$3:$H$248,H20) -> 1 | K20: Yes
A21: 26 | B21: ▶ Play | C21: music/Broken By Grace (Country).mp3 | D21: Broken by Grace (Country) | E21: RRN | F21: Christian Country | G21: Country | H21: Broken by Grace | I21: =COUNTIF($H$3:$H$248,H21) -> 1 | J21: NEW | K21: Yes
A22: 27 | B22: ▶ Play | C22: music/Broken Chains Psychedelic Rock Version (1).mp3 | D22: Broken Chains (Psychedelic Christian Rock) | E22: RRN | F22: Psychedelic Christian Rock | G22: Psychedelic Christian Rock | H22: Broken Chains Version | I22: =COUNTIF($H$3:$H$248,H22) -> 1 | K22: Yes
A23: 29 | B23: ▶ Play | C23: music/Brook_Code.mp3 | D23: Brook Code (Teaching) | E23: RRN Teaching | F23: Biblical Teaching | G23: Teaching | H23: Brook Code | I23: =COUNTIF($H$3:$H$248,H23) -> 1 | K23: Yes
A24: 30 | B24: ▶ Play | C24: music/CALLED BY NAME (I AM YOURS) (1).mp3 | D24: Called by Name (I Am Yours) (EDM) | E24: RRN | F24: Christian EDM | G24: EDM | H24: Called by Name | I24: =COUNTIF($H$3:$H$248,H24) -> 1 | K24: Yes
A25: 32 | B25: ▶ Play | C25: music/Called From the Low Places (1).mp3 | D25: Called from the Low Places (Southern Blues Rock) | E25: RRN | F25: Christian Southern Blues Rock | G25: Southern Blues Rock | H25: Called from the Low Places | I25: =COUNTIF($H$3:$H$248,H25) -> 1 | K25: Yes
A26: 36 | B26: ▶ Play | C26: music/CHAOS VS CALLING (1).mp3 | D26: Chaos vs. Calling (EDM) | E26: RRN | F26: Christian EDM | G26: EDM | H26: Chaos Vs Calling | I26: =COUNTIF($H$3:$H$248,H26) -> 1 | K26: Yes
A27: 38 | B27: ▶ Play | C27: music/Church N Chicken Bounce Drop Country Rap.mp3 | D27: Church N Chicken (Country Rap Bounce Mix) | E27: RRN | F27: Christian Bounce Drop | G27: Bounce Drop | H27: Church N Chicken | I27: =COUNTIF($H$3:$H$248,H27) -> 1 | K27: Yes
A28: 40 | B28: ▶ Play | C28: music/Clock Won’t Let Go Bounce Drop Country Rap.mp3 | D28: Clock Won't Let Go (Country Rap Bounce Mix) | E28: RRN | F28: Christian Bounce Drop | G28: Bounce Drop | H28: Clock Won’t Let Go | I28: =COUNTIF($H$3:$H$248,H28) -> 1 | K28: Yes
A29: 42 | B29: ▶ Play | C29: music/Closer Than My Breath Pop.mp3 | D29: Closer Than My Breath (Pop) | E29: RRN | F29: Christian Pop | G29: Pop | H29: Closer Than My Breath | I29: =COUNTIF($H$3:$H$248,H29) -> 1 | K29: Yes
A30: 43 | B30: ▶ Play | C30: music/Clothed in Your Glory (R&B).mp3 | D30: Clothed in Your Glory (R&B) | E30: RRN | F30: Christian R&B | G30: R&B | H30: Clothed in Your Glory | I30: =COUNTIF($H$3:$H$248,H30) -> 1 | J30: NEW | K30: Yes
A31: 44 | B31: ▶ Play | C31: music/Come Alive (Chains Fall Down) Radio.mp3 | D31: Come Alive (Chains Fall Down) (Pop) | E31: RRN | F31: Christian Pop | G31: Pop | H31: Come Alive | I31: =COUNTIF($H$3:$H$248,H31) -> 2 | K31: Yes
A32: 45 | B32: ▶ Play | C32: music/Come Alive (Chains Fall Down).mp3 | D32: Come Alive (Praise & Worship) | E32: RRN | F32: Praise & Worship | G32: Praise & Worship | H32: Come Alive | I32: =COUNTIF($H$3:$H$248,H32) -> 2 | K32: Yes
A33: 46 | B33: ▶ Play | C33: music/Come Alive (Chains Fall Down) Radio (1).mp3 | D33: Come Alive (Chains Fall Down) (Radio Edit) | E33: RRN | F33: Christian Pop | G33: Pop | H33: Come Alive Radio | I33: =COUNTIF($H$3:$H$248,H33) -> 1 | K33: Yes
A34: 47 | B34: ▶ Play | C34: music/Consuming Fire Country.mp3 | D34: Consuming Fire (Country) | E34: RRN | F34: Christian Country | G34: Country | H34: Consuming Fire | I34: =COUNTIF($H$3:$H$248,H34) -> 2 | K34: Yes
A35: 48 | B35: ▶ Play | C35: music/Consuming Fire (1).mp3 | D35: Consuming Fire (Pop) | E35: RRN | F35: Christian Pop | G35: Pop | H35: Consuming Fire | I35: =COUNTIF($H$3:$H$248,H35) -> 2 | K35: Yes
A36: 50 | B36: ▶ Play | C36: music/Consuming Fire Jazz.mp3 | D36: Consuming Fire (Blues Jazz Version) | E36: RRN | F36: Christian Blues-Jazz | G36: Blues-Jazz | H36: Consuming Fire Jazz | I36: =COUNTIF($H$3:$H$248,H36) -> 1 | K36: Yes
A37: 51 | B37: ▶ Play | C37: music/CROWN OF THORNS, HANDS OF GRACE— Post-Grunge.mp3 | D37: Crown of Thorns, Hands of Grace (Worship Rock) | E37: RRN | F37: Worship Rock | G37: Worship Rock | H37: Crown of Thorns, Hands of Grace | I37: =COUNTIF($H$3:$H$248,H37) -> 1 | K37: Yes
A38: 52 | B38: ▶ Play | C38: music/Daughter Again EDM (1).mp3 | D38: Daughter Again (EDM) | E38: RRN | F38: Christian EDM | G38: EDM | H38: Daughter Again | I38: =COUNTIF($H$3:$H$248,H38) -> 2 | K38: Yes
A39: 54 | B39: ▶ Play | C39: music/Daughter Again Pop (1).mp3 | D39: Daughter Again (Pop) | E39: RRN | F39: Christian Pop | G39: Pop | H39: Daughter Again | I39: =COUNTIF($H$3:$H$248,H39) -> 2 | K39: Yes
A40: 56 | B40: ▶ Play | C40: music/Devil_Under_My_Soles.mp3 | D40: Devil Under My Soles (Pop) | E40: RRN | F40: Christian Pop | G40: Pop | H40: Devil Under My Soles | I40: =COUNTIF($H$3:$H$248,H40) -> 1 | K40: Yes
...

Sheet Rotation Rules
A1: Rule | B1: Value | C1: What it does
A2: Family cooldown (minutes) | B2: 120 | C2: No version of a song within this window.
A3: Play-all rotation | B3: Yes | C3: Every song is always eligible; the whole catalog cycles before anything repeats.
A4: No immediate repeat | B4: Yes | C4: Never twice back-to-back.
A5: Orphan genres always eligible | B5: Yes | C5: Songs with no daypart still air.
A6: Bounce drops as specialty | B6: Yes | C6: Bounce sprinkles between songs.
A7: Biblical Teaching as segments | B7: Yes | C7: Teaching airs as segments.
A8: Follow daypart clock | B8: No | C8: OFF — full play-all: every song airs at any hour (dayparts no longer gate the music).

Sheet Dayparts
A1: Daypart Name | B1: Start Hour | C1: End Hour | D1: Genres (semicolon-separated) | E1: Specialty
A2: Healing & Recovery | B2: 0 | C2: 6 | D2: praise & worship; contemporary worship; worship rock; christian chillwave; christian blues-jazz; testimony; testimony songs
A3: Morning Motivation | B3: 6 | C3: 10 | D3: christian pop; southern christian rock; worship rock; christian country; praise & worship | E3: bounce
A4: Christian 80s Lunch | B4: 10 | C4: 14 | D4: christian pop; southern christian rock; christian country; christian country - pop | E4: 80s
A5: Workday Encouragement | B5: 14 | C5: 17 | D5: christian country; southern christian rock; christian pop; christian soul | E5: bounce
A6: Drive Time | B6: 17 | C6: 20 | D6: southern christian rock; christian country; christian pop; christian 80's
A7: Night Energy | B7: 20 | C7: 24 | D7: christian edm; christian dance; christian k-pop; christian trip-hop | E7: bounce

Sheet Genres
A1: Genre | B1: Songs | C1: In a Daypart?
A2: Biblical Teaching | B2: =COUNTIF('Song Library'!$F$3:$F$248,A2) -> 9 | C2: No — always-eligible
A3: Christian 2000s Alternative Metal | B3: =COUNTIF('Song Library'!$F$3:$F$248,A3) -> 3 | C3: No — always-eligible
A4: Christian 80's | B4: =COUNTIF('Song Library'!$F$3:$F$248,A4) -> 7 | C4: Yes
A5: Christian Alternative R&B | B5: =COUNTIF('Song Library'!$F$3:$F$248,A5) -> 9 | C5: No — always-eligible
A6: Christian Alternative Rock | B6: =COUNTIF('Song Library'!$F$3:$F$248,A6) -> 4 | C6: No — always-eligible
A7: Christian Bluegrass | B7: =COUNTIF('Song Library'!$F$3:$F$248,A7) -> 3 | C7: No — always-eligible
A8: Christian Blues-Jazz | B8: =COUNTIF('Song Library'!$F$3:$F$248,A8) -> 4 | C8: Yes
A9: Christian Bounce Drop | B9: =COUNTIF('Song Library'!$F$3:$F$248,A9) -> 12 | C9: No — always-eligible
A10: Christian Chillwave | B10: =COUNTIF('Song Library'!$F$3:$F$248,A10) -> 5 | C10: Yes
A11: Christian Country | B11: =COUNTIF('Song Library'!$F$3:$F$248,A11) -> 10 | C11: Yes
A12: Christian Country - Pop | B12: =COUNTIF('Song Library'!$F$3:$F$248,A12) -> 6 | C12: Yes
A13: Christian Dance | B13: =COUNTIF('Song Library'!$F$3:$F$248,A13) -> 7 | C13: Yes
... A34: Worship Rock | B34: =COUNTIF('Song Library'!$F$3:$F$248,A34) -> 6 | C34: Yes
